Error: Message: Tried to run command without establishing a connection

Error turning page!
Traceback (most recent call last):
  File "get_news.py", line 11, in <module>
    data = streamer.run()
  File "/home/ubuntu/Nasdaq_Data_Gatherer/scripts/nasdaqAPI.py", line 90, in run
    self._close_browser("News")
  File "/home/ubuntu/Nasdaq_Data_Gatherer/scripts/nasdaqAPI.py", line 193, in _close_browser
    self.nasdaqNewsBrowser.close()
  File "/home/ubuntu/.local/lib/python3.6/site-packages/selenium/webdriver/remote/webdriver.py", line 688, in close
    self.execute(Command.CLOSE)
  File "/home/ubuntu/.local/lib/python3.6/site-packages/selenium/webdriver/remote/webdriver.py", line 321, in execute
    self.error_handler.check_response(response)
  File "/home/ubuntu/.local/lib/python3.6/site-packages/selenium/webdriver/remote/errorhandler.py", line 242, in check_response
    raise exception_class(message, screen, stacktrace)
selenium.common.exceptions.InvalidSessionIdException: Message: Tried to run command without establishing a connection

Error: HTTPConnectionPool(host='127.0.0.1', port=59201): Max retries exceeded with url: /session/141a06c0-8943-4fd3-9b73-3dac6299d011/element (Caused by NewConnectionError('<urllib3.connection.HTTPConnection object at 0x7f50545ac828>: Failed to establish a new connection: [Errno 111] Connection refused',))
Error turning page!
Traceback (most recent call last):
  File "/home/ubuntu/.local/lib/python3.6/site-packages/urllib3/connection.py", line 160, in _new_conn
    (self._dns_host, self.port), self.timeout, **extra_kw
  File "/home/ubuntu/.local/lib/python3.6/site-packages/urllib3/util/connection.py", line 84, in create_connection
    raise err
  File "/home/ubuntu/.local/lib/python3.6/site-packages/urllib3/util/connection.py", line 74, in create_connection
    sock.connect(sa)
ConnectionRefusedError: [Errno 111] Connection refused

During handling of the above exception, another exception occurred:

Traceback (most recent call last):
  File "/home/ubuntu/.local/lib/python3.6/site-packages/urllib3/connectionpool.py", line 677, in urlopen
    chunked=chunked,
  File "/home/ubuntu/.local/lib/python3.6/site-packages/urllib3/connectionpool.py", line 392, in _make_request
    conn.request(method, url, **httplib_request_kw)
  File "/usr/lib/python3.6/http/client.py", line 1264, in request
    self._send_request(method, url, body, headers, encode_chunked)
  File "/usr/lib/python3.6/http/client.py", line 1310, in _send_request
    self.endheaders(body, encode_chunked=encode_chunked)
  File "/usr/lib/python3.6/http/client.py", line 1259, in endheaders
    self._send_output(message_body, encode_chunked=encode_chunked)
  File "/usr/lib/python3.6/http/client.py", line 1038, in _send_output
    self.send(msg)
  File "/usr/lib/python3.6/http/client.py", line 976, in send
    self.connect()
  File "/home/ubuntu/.local/lib/python3.6/site-packages/urllib3/connection.py", line 187, in connect
    conn = self._new_conn()
  File "/home/ubuntu/.local/lib/python3.6/site-packages/urllib3/connection.py", line 172, in _new_conn
    self, "Failed to establish a new connection: %s" % e
urllib3.exceptions.NewConnectionError: <urllib3.connection.HTTPConnection object at 0x7f50545ac198>: Failed to establish a new connection: [Errno 111] Connection refused

During handling of the above exception, another exception occurred:

Traceback (most recent call last):
  File "get_news.py", line 11, in <module>
    data = streamer.run()
  File "/home/ubuntu/Nasdaq_Data_Gatherer/scripts/nasdaqAPI.py", line 90, in run
    self._close_browser("News")
  File "/home/ubuntu/Nasdaq_Data_Gatherer/scripts/nasdaqAPI.py", line 193, in _close_browser
    self.nasdaqNewsBrowser.close()
  File "/home/ubuntu/.local/lib/python3.6/site-packages/selenium/webdriver/remote/webdriver.py", line 688, in close
    self.execute(Command.CLOSE)
  File "/home/ubuntu/.local/lib/python3.6/site-packages/selenium/webdriver/remote/webdriver.py", line 319, in execute
    response = self.command_executor.execute(driver_command, params)
  File "/home/ubuntu/.local/lib/python3.6/site-packages/selenium/webdriver/remote/remote_connection.py", line 374, in execute
    return self._request(command_info[0], url, body=data)
  File "/home/ubuntu/.local/lib/python3.6/site-packages/selenium/webdriver/remote/remote_connection.py", line 397, in _request
    resp = self._conn.request(method, url, body=body, headers=headers)
  File "/home/ubuntu/.local/lib/python3.6/site-packages/urllib3/request.py", line 76, in request
    method, url, fields=fields, headers=headers, **urlopen_kw
  File "/home/ubuntu/.local/lib/python3.6/site-packages/urllib3/request.py", line 97, in request_encode_url
    return self.urlopen(method, url, **extra_kw)
  File "/home/ubuntu/.local/lib/python3.6/site-packages/urllib3/poolmanager.py", line 336, in urlopen
    response = conn.urlopen(method, u.request_uri, **kw)
  File "/home/ubuntu/.local/lib/python3.6/site-packages/urllib3/connectionpool.py", line 765, in urlopen
    **response_kw
  File "/home/ubuntu/.local/lib/python3.6/site-packages/urllib3/connectionpool.py", line 765, in urlopen
    **response_kw
  File "/home/ubuntu/.local/lib/python3.6/site-packages/urllib3/connectionpool.py", line 765, in urlopen
    **response_kw
  File "/home/ubuntu/.local/lib/python3.6/site-packages/urllib3/connectionpool.py", line 725, in urlopen
    method, url, error=e, _pool=self, _stacktrace=sys.exc_info()[2]
  File "/home/ubuntu/.local/lib/python3.6/site-packages/urllib3/util/retry.py", line 439, in increment
    raise MaxRetryError(_pool, url, error or ResponseError(cause))
urllib3.exceptions.MaxRetryError: HTTPConnectionPool(host='127.0.0.1', port=59201): Max retries exceeded with url: /session/141a06c0-8943-4fd3-9b73-3dac6299d011/window (Caused by NewConnectionError('<urllib3.connection.HTTPConnection object at 0x7f50545ac198>: Failed to establish a new connection: [Errno 111] Connection refused',))
Error: Message: Failed to decode response from marionette

Error turning page!
Traceback (most recent call last):
  File "get_news.py", line 11, in <module>
    data = streamer.run()
  File "/home/ubuntu/Nasdaq_Data_Gatherer/scripts/nasdaqAPI.py", line 90, in run
    self._close_browser("News")
  File "/home/ubuntu/Nasdaq_Data_Gatherer/scripts/nasdaqAPI.py", line 193, in _close_browser
    self.nasdaqNewsBrowser.close()
  File "/home/ubuntu/.local/lib/python3.6/site-packages/selenium/webdriver/remote/webdriver.py", line 688, in close
    self.execute(Command.CLOSE)
  File "/home/ubuntu/.local/lib/python3.6/site-packages/selenium/webdriver/remote/webdriver.py", line 321, in execute
    self.error_handler.check_response(response)
  File "/home/ubuntu/.local/lib/python3.6/site-packages/selenium/webdriver/remote/errorhandler.py", line 242, in check_response
    raise exception_class(message, screen, stacktrace)
selenium.common.exceptions.InvalidSessionIdException: Message: Tried to run command without establishing a connection

Traceback (most recent call last):
  File "get_news.py", line 11, in <module>
    data = streamer.run()
  File "/home/ubuntu/Nasdaq_Data_Gatherer/scripts/nasdaqAPI.py", line 88, in run
    self._init_browser("News")
  File "/home/ubuntu/Nasdaq_Data_Gatherer/scripts/nasdaqAPI.py", line 156, in _init_browser
    self.nasdaqNewsBrowser.get(self.nasdaqUrl_News)
  File "/home/ubuntu/.local/lib/python3.6/site-packages/selenium/webdriver/remote/webdriver.py", line 333, in get
    self.execute(Command.GET, {'url': url})
  File "/home/ubuntu/.local/lib/python3.6/site-packages/selenium/webdriver/remote/webdriver.py", line 319, in execute
    response = self.command_executor.execute(driver_command, params)
  File "/home/ubuntu/.local/lib/python3.6/site-packages/selenium/webdriver/remote/remote_connection.py", line 374, in execute
    return self._request(command_info[0], url, body=data)
  File "/home/ubuntu/.local/lib/python3.6/site-packages/selenium/webdriver/remote/remote_connection.py", line 397, in _request
    resp = self._conn.request(method, url, body=body, headers=headers)
  File "/home/ubuntu/.local/lib/python3.6/site-packages/urllib3/request.py", line 80, in request
    method, url, fields=fields, headers=headers, **urlopen_kw
  File "/home/ubuntu/.local/lib/python3.6/site-packages/urllib3/request.py", line 171, in request_encode_body
    return self.urlopen(method, url, **extra_kw)
  File "/home/ubuntu/.local/lib/python3.6/site-packages/urllib3/poolmanager.py", line 336, in urlopen
    response = conn.urlopen(method, u.request_uri, **kw)
  File "/home/ubuntu/.local/lib/python3.6/site-packages/urllib3/connectionpool.py", line 677, in urlopen
    chunked=chunked,
  File "/home/ubuntu/.local/lib/python3.6/site-packages/urllib3/connectionpool.py", line 426, in _make_request
    six.raise_from(e, None)
  File "<string>", line 3, in raise_from
  File "/home/ubuntu/.local/lib/python3.6/site-packages/urllib3/connectionpool.py", line 421, in _make_request
    httplib_response = conn.getresponse()
  File "/usr/lib/python3.6/http/client.py", line 1356, in getresponse
    response.begin()
  File "/usr/lib/python3.6/http/client.py", line 307, in begin
    version, status, reason = self._read_status()
  File "/usr/lib/python3.6/http/client.py", line 268, in _read_status
    line = str(self.fp.readline(_MAXLINE + 1), "iso-8859-1")
  File "/usr/lib/python3.6/socket.py", line 586, in readinto
    return self._sock.recv_into(b)
KeyboardInterrupt
Error: Message: Tried to run command without establishing a connection

Error turning page!
Traceback (most recent call last):
  File "get_news.py", line 11, in <module>
    data = streamer.run()
  File "/home/ubuntu/Nasdaq_Data_Gatherer/scripts/nasdaqAPI.py", line 90, in run
    self._close_browser("News")
  File "/home/ubuntu/Nasdaq_Data_Gatherer/scripts/nasdaqAPI.py", line 193, in _close_browser
    self.nasdaqNewsBrowser.close()
  File "/home/ubuntu/.local/lib/python3.6/site-packages/selenium/webdriver/remote/webdriver.py", line 688, in close
    self.execute(Command.CLOSE)
  File "/home/ubuntu/.local/lib/python3.6/site-packages/selenium/webdriver/remote/webdriver.py", line 321, in execute
    self.error_handler.check_response(response)
  File "/home/ubuntu/.local/lib/python3.6/site-packages/selenium/webdriver/remote/errorhandler.py", line 242, in check_response
    raise exception_class(message, screen, stacktrace)
selenium.common.exceptions.InvalidSessionIdException: Message: Tried to run command without establishing a connection

